<!DOCTYPE html>
<html lang="en">
<head>
  <meta charset="UTF-8">
  <title>08_promise的几个关键问题5</title>
</head>
<body>
<script>
/*
  6. `promise` 异常穿透？
    + 当使用 `promise` 的 `then` 链式调用时，可以在最后指定失败的回调
    + 前面的操作出了异常，都会传到最后失败的回调中处理
  7. 中断 `promise` 链？
    + 当使用 `promise` 的 `then` 链式调用时，在中间中断，不再调用后面的回调函数
    + 办法：在回调函数中返回一个 `pending` 状态的 `promise` 对象
 */
new Promise((resolve, reject) => {
  // resolve(1)
  reject(1)
}).then(
  value => {
    console.log("onResolved1()：", value)
    return 2
  },
  reason => { throw reason }
).then(
  value => {
    console.log("onResolved2()：", value)
    return 3
  },
  reason => { throw reason }
).then(
  value => {
    console.log("onResolved3()：", value)
  },
  reason => { throw reason }
).catch(reason => {
  console.log("onRejected()", reason)
  // throw reason
  // return Promise.reject(reason)
  return new Promise(()=>{}) // 返回一个 pending 的 promise  中断 promise 链
}).then(
  value => {
    console.log("onResolved4()：", value)
  },
  reason => {
    console.log("onRejected2()：", reason)
  }
)

</script>
</body>
</html>