<!DOCTYPE html>
<html lang="en">
<head>
  <meta charset="UTF-8">
  <title>01_async和await</title>
</head>
<body>
<script>
  /*
  1.`async` 函数
    + 函数的返回值为 `promise` 对象
    + `promise` 对象的结果由 `async` 函数执行的返回值决定
  2. `await` 表达式
    + `await` 右侧的表达式一般为 `promise` 对象，但也可以是其他的值
    + 如果表达式是 `promise` 对象，`await` 返回的是 `promise` 成功的值
  3. 注意
    + `await` 必须写在 `async` 函数中，但 `async` 函数中可以没有 `await`
    + 如果 `await` 的 `promise` 失败了，就会抛出异常，需要通过 `try...catch` 来捕获处理
   */

  // async 函数的返回值是一个 promise 对象
  // async 函数的返回的 promise 的结果由函数执行的结果决定
  async function fn1() {
    return 1
  }
  async function fn1_1() {
    throw 2
  }
  async function fn1_2() {
    return Promise.resolve(3)
  }
  async function fn1_3() {
    return Promise.reject(4)
  }
  async function fn1_4() {
    return new Promise((resolve, reject)=>{
      setTimeout(()=>{
        resolve(5)
      }, 1000)
    })
  }

  const result = fn1()
  console.log(result)
  const result1 = fn1_1()
  console.log(result1)
  const result2 = fn1_2()
  const result3 = fn1_3()
  const result4 = fn1_4()
  /*
    Promise {<fulfilled>: 1}
      __proto__: Promise
      [[PromiseState]]: "fulfilled"
      [[PromiseResult]]: 1
    Promise {<rejected>: 2}
      __proto__: Promise
      [[PromiseState]]: "rejected"
      [[PromiseResult]]: 2
  */
  result.then(value => { console.log('result', value) })
  result1.catch(reason => { console.log('result1', reason) })
  result2.then(value => { console.log('result2', value) })
  result3.catch(reason => { console.log('result3', reason) })
  result4.then(value => { console.log('result4', value) })
  /*
    result 1
    result1 2
    result2 3
    result3 4
    result4 5
  */
  function fn2() {
    return new Promise((resolve, reject)=>{
      setTimeout(()=>{
        resolve(6)
      }, 1000)
    })
  }
  function fn2_1() {
    return new Promise((resolve, reject)=>{
      setTimeout(()=>{
        reject(9)
      }, 1000)
    })
  }
  function fn4() {
    return 8
  }
  async function fn3() {
    const value = await fn2() // await 右侧表达式为 promise，得到的结果就是 promise 成功的 value
    console.log("value", value) // value 6
  }
  async function fn3_1() {
    const value = await 7 // await 右侧表达式不是 promise，得到的结果就是这个值本身（表达式的值）
    console.log("value", value) // value 7
  }
  async function fn3_2() {
    const value = await fn4() // await 右侧表达式不是 promise，得到的结果就是这个值本身（表达式的值）
    console.log("value", value) // value 8
  }
  async function fn3_3() {
    try {
      const value = await fn2_1()
      console.log("value", value)
    } catch (error) {
      console.log("得到失败的结果", error) // 得到失败的结果 9
    }
  }
  fn3()
  fn3_1()
  fn3_2()
  fn3_3()
</script>
</body>
</html>